[2023-12-13T10:28:57.995+0000] {taskinstance.py:1159} INFO - Dependencies all met for dep_context=non-requeueable deps ti=<TaskInstance: pipeline.s3_file_upload manual__2023-12-13T10:28:56.150093+00:00 [queued]>
[2023-12-13T10:28:57.999+0000] {taskinstance.py:1159} INFO - Dependencies all met for dep_context=requeueable deps ti=<TaskInstance: pipeline.s3_file_upload manual__2023-12-13T10:28:56.150093+00:00 [queued]>
[2023-12-13T10:28:57.999+0000] {taskinstance.py:1361} INFO - Starting attempt 1 of 3
[2023-12-13T10:28:58.004+0000] {taskinstance.py:1382} INFO - Executing <Task(PythonOperator): s3_file_upload> on 2023-12-13 10:28:56.150093+00:00
[2023-12-13T10:28:58.010+0000] {standard_task_runner.py:57} INFO - Started process 1157 to run task
[2023-12-13T10:28:58.014+0000] {standard_task_runner.py:84} INFO - Running: ['***', 'tasks', 'run', 'pipeline', 's3_file_upload', 'manual__2023-12-13T10:28:56.150093+00:00', '--job-id', '64', '--raw', '--subdir', 'DAGS_FOLDER/local_s3_snowflake.py', '--cfg-path', '/tmp/tmplz66bzwj']
[2023-12-13T10:28:58.017+0000] {standard_task_runner.py:85} INFO - Job 64: Subtask s3_file_upload
[2023-12-13T10:28:58.058+0000] {task_command.py:416} INFO - Running <TaskInstance: pipeline.s3_file_upload manual__2023-12-13T10:28:56.150093+00:00 [running]> on host 396cdce1f317
[2023-12-13T10:28:58.106+0000] {taskinstance.py:1662} INFO - Exporting env vars: AIRFLOW_CTX_DAG_OWNER='sarthak' AIRFLOW_CTX_DAG_ID='pipeline' AIRFLOW_CTX_TASK_ID='s3_file_upload' AIRFLOW_CTX_EXECUTION_DATE='2023-12-13T10:28:56.150093+00:00' AIRFLOW_CTX_TRY_NUMBER='1' AIRFLOW_CTX_DAG_RUN_ID='manual__2023-12-13T10:28:56.150093+00:00'
[2023-12-13T10:28:59.692+0000] {taskinstance.py:1937} ERROR - Task failed with exception
Traceback (most recent call last):
  File "/home/airflow/.local/lib/python3.8/site-packages/boto3/s3/transfer.py", line 292, in upload_file
    future.result()
  File "/home/airflow/.local/lib/python3.8/site-packages/s3transfer/futures.py", line 103, in result
    return self._coordinator.result()
  File "/home/airflow/.local/lib/python3.8/site-packages/s3transfer/futures.py", line 266, in result
    raise self._exception
  File "/home/airflow/.local/lib/python3.8/site-packages/s3transfer/tasks.py", line 139, in __call__
    return self._execute_main(kwargs)
  File "/home/airflow/.local/lib/python3.8/site-packages/s3transfer/tasks.py", line 162, in _execute_main
    return_value = self._main(**kwargs)
  File "/home/airflow/.local/lib/python3.8/site-packages/s3transfer/upload.py", line 764, in _main
    client.put_object(Bucket=bucket, Key=key, Body=body, **extra_args)
  File "/home/airflow/.local/lib/python3.8/site-packages/botocore/client.py", line 535, in _api_call
    return self._make_api_call(operation_name, kwargs)
  File "/home/airflow/.local/lib/python3.8/site-packages/botocore/client.py", line 980, in _make_api_call
    raise error_class(parsed_response, operation_name)
botocore.errorfactory.NoSuchBucket: An error occurred (NoSuchBucket) when calling the PutObject operation: The specified bucket does not exist

During handling of the above exception, another exception occurred:

Traceback (most recent call last):
  File "/home/airflow/.local/lib/python3.8/site-packages/airflow/operators/python.py", line 192, in execute
    return_value = self.execute_callable()
  File "/home/airflow/.local/lib/python3.8/site-packages/airflow/operators/python.py", line 209, in execute_callable
    return self.python_callable(*self.op_args, **self.op_kwargs)
  File "/opt/airflow/dags/local_s3_snowflake.py", line 32, in upload_file
    client.upload_file('/opt/airflow/files/organizations-100.csv', 'sarthak-aws-bucket-004', 'Organizations-file')
  File "/home/airflow/.local/lib/python3.8/site-packages/boto3/s3/inject.py", line 143, in upload_file
    return transfer.upload_file(
  File "/home/airflow/.local/lib/python3.8/site-packages/boto3/s3/transfer.py", line 298, in upload_file
    raise S3UploadFailedError(
boto3.exceptions.S3UploadFailedError: Failed to upload /opt/***/files/organizations-100.csv to sarthak-aws-bucket-004/Organizations-file: An error occurred (NoSuchBucket) when calling the PutObject operation: The specified bucket does not exist
[2023-12-13T10:28:59.699+0000] {taskinstance.py:1400} INFO - Marking task as UP_FOR_RETRY. dag_id=pipeline, task_id=s3_file_upload, execution_date=20231213T102856, start_date=20231213T102857, end_date=20231213T102859
[2023-12-13T10:28:59.706+0000] {standard_task_runner.py:104} ERROR - Failed to execute job 64 for task s3_file_upload (Failed to upload /opt/***/files/organizations-100.csv to sarthak-aws-bucket-004/Organizations-file: An error occurred (NoSuchBucket) when calling the PutObject operation: The specified bucket does not exist; 1157)
[2023-12-13T10:28:59.757+0000] {local_task_job_runner.py:228} INFO - Task exited with return code 1
[2023-12-13T10:28:59.771+0000] {taskinstance.py:2778} INFO - 0 downstream tasks scheduled from follow-on schedule check
