[2023-12-11T20:02:28.952+0000] {taskinstance.py:1159} INFO - Dependencies all met for dep_context=non-requeueable deps ti=<TaskInstance: s3_hook_overview.upload_to_snowflake manual__2023-12-11T19:57:06.338532+00:00 [queued]>
[2023-12-11T20:02:28.960+0000] {taskinstance.py:1159} INFO - Dependencies all met for dep_context=requeueable deps ti=<TaskInstance: s3_hook_overview.upload_to_snowflake manual__2023-12-11T19:57:06.338532+00:00 [queued]>
[2023-12-11T20:02:28.961+0000] {taskinstance.py:1361} INFO - Starting attempt 2 of 2
[2023-12-11T20:02:28.971+0000] {taskinstance.py:1382} INFO - Executing <Task(PythonOperator): upload_to_snowflake> on 2023-12-11 19:57:06.338532+00:00
[2023-12-11T20:02:28.975+0000] {standard_task_runner.py:57} INFO - Started process 5454 to run task
[2023-12-11T20:02:28.978+0000] {standard_task_runner.py:84} INFO - Running: ['***', 'tasks', 'run', 's3_hook_overview', 'upload_to_snowflake', 'manual__2023-12-11T19:57:06.338532+00:00', '--job-id', '32', '--raw', '--subdir', 'DAGS_FOLDER/load_into_snowflake.py', '--cfg-path', '/tmp/tmpxaoqkd8f']
[2023-12-11T20:02:28.979+0000] {standard_task_runner.py:85} INFO - Job 32: Subtask upload_to_snowflake
[2023-12-11T20:02:29.004+0000] {task_command.py:416} INFO - Running <TaskInstance: s3_hook_overview.upload_to_snowflake manual__2023-12-11T19:57:06.338532+00:00 [running]> on host a3992be7c3a0
[2023-12-11T20:02:29.038+0000] {taskinstance.py:1662} INFO - Exporting env vars: AIRFLOW_CTX_DAG_OWNER='***' AIRFLOW_CTX_DAG_ID='s3_hook_overview' AIRFLOW_CTX_TASK_ID='upload_to_snowflake' AIRFLOW_CTX_EXECUTION_DATE='2023-12-11T19:57:06.338532+00:00' AIRFLOW_CTX_TRY_NUMBER='2' AIRFLOW_CTX_DAG_RUN_ID='manual__2023-12-11T19:57:06.338532+00:00'
[2023-12-11T20:02:29.048+0000] {taskinstance.py:1937} ERROR - Task failed with exception
Traceback (most recent call last):
  File "/home/airflow/.local/lib/python3.8/site-packages/airflow/operators/python.py", line 192, in execute
    return_value = self.execute_callable()
  File "/home/airflow/.local/lib/python3.8/site-packages/airflow/operators/python.py", line 209, in execute_callable
    return self.python_callable(*self.op_args, **self.op_kwargs)
  File "/opt/airflow/dags/load_into_snowflake.py", line 169, in upload_to_snowflake
    snowflake_task = CopyFromExternalStageToSnowflakeOperator(
  File "/home/airflow/.local/lib/python3.8/site-packages/airflow/models/baseoperator.py", line 420, in apply_defaults
    raise AirflowException(f"missing keyword argument {missing_args.pop()!r}")
airflow.exceptions.AirflowException: missing keyword argument 'stage'
[2023-12-11T20:02:29.051+0000] {taskinstance.py:1400} INFO - Marking task as FAILED. dag_id=s3_hook_overview, task_id=upload_to_snowflake, execution_date=20231211T195706, start_date=20231211T200228, end_date=20231211T200229
[2023-12-11T20:02:29.056+0000] {standard_task_runner.py:104} ERROR - Failed to execute job 32 for task upload_to_snowflake (missing keyword argument 'stage'; 5454)
[2023-12-11T20:02:29.071+0000] {local_task_job_runner.py:228} INFO - Task exited with return code 1
[2023-12-11T20:02:29.080+0000] {taskinstance.py:2778} INFO - 0 downstream tasks scheduled from follow-on schedule check
