[2023-12-11T18:20:45.111+0000] {taskinstance.py:1159} INFO - Dependencies all met for dep_context=non-requeueable deps ti=<TaskInstance: s3_upload.s3_file_upload manual__2023-12-11T18:20:23.010514+00:00 [queued]>
[2023-12-11T18:20:45.116+0000] {taskinstance.py:1159} INFO - Dependencies all met for dep_context=requeueable deps ti=<TaskInstance: s3_upload.s3_file_upload manual__2023-12-11T18:20:23.010514+00:00 [queued]>
[2023-12-11T18:20:45.116+0000] {taskinstance.py:1361} INFO - Starting attempt 4 of 4
[2023-12-11T18:20:45.122+0000] {taskinstance.py:1382} INFO - Executing <Task(PythonOperator): s3_file_upload> on 2023-12-11 18:20:23.010514+00:00
[2023-12-11T18:20:45.124+0000] {standard_task_runner.py:57} INFO - Started process 1859 to run task
[2023-12-11T18:20:45.127+0000] {standard_task_runner.py:84} INFO - Running: ['***', 'tasks', 'run', 's3_upload', 's3_file_upload', 'manual__2023-12-11T18:20:23.010514+00:00', '--job-id', '13', '--raw', '--subdir', 'DAGS_FOLDER/s3_upload_dag.py', '--cfg-path', '/tmp/tmplcl_fts8']
[2023-12-11T18:20:45.128+0000] {standard_task_runner.py:85} INFO - Job 13: Subtask s3_file_upload
[2023-12-11T18:20:45.152+0000] {task_command.py:416} INFO - Running <TaskInstance: s3_upload.s3_file_upload manual__2023-12-11T18:20:23.010514+00:00 [running]> on host a3992be7c3a0
[2023-12-11T18:20:45.189+0000] {taskinstance.py:1662} INFO - Exporting env vars: AIRFLOW_CTX_DAG_OWNER='sarthak' AIRFLOW_CTX_DAG_ID='s3_upload' AIRFLOW_CTX_TASK_ID='s3_file_upload' AIRFLOW_CTX_EXECUTION_DATE='2023-12-11T18:20:23.010514+00:00' AIRFLOW_CTX_TRY_NUMBER='4' AIRFLOW_CTX_DAG_RUN_ID='manual__2023-12-11T18:20:23.010514+00:00'
[2023-12-11T18:20:46.631+0000] {taskinstance.py:1937} ERROR - Task failed with exception
Traceback (most recent call last):
  File "/home/airflow/.local/lib/python3.8/site-packages/boto3/s3/transfer.py", line 292, in upload_file
    future.result()
  File "/home/airflow/.local/lib/python3.8/site-packages/s3transfer/futures.py", line 103, in result
    return self._coordinator.result()
  File "/home/airflow/.local/lib/python3.8/site-packages/s3transfer/futures.py", line 266, in result
    raise self._exception
  File "/home/airflow/.local/lib/python3.8/site-packages/s3transfer/tasks.py", line 139, in __call__
    return self._execute_main(kwargs)
  File "/home/airflow/.local/lib/python3.8/site-packages/s3transfer/tasks.py", line 162, in _execute_main
    return_value = self._main(**kwargs)
  File "/home/airflow/.local/lib/python3.8/site-packages/s3transfer/tasks.py", line 348, in _main
    response = client.create_multipart_upload(
  File "/home/airflow/.local/lib/python3.8/site-packages/botocore/client.py", line 535, in _api_call
    return self._make_api_call(operation_name, kwargs)
  File "/home/airflow/.local/lib/python3.8/site-packages/botocore/client.py", line 980, in _make_api_call
    raise error_class(parsed_response, operation_name)
botocore.exceptions.ClientError: An error occurred (InvalidAccessKeyId) when calling the CreateMultipartUpload operation: The AWS Access Key Id you provided does not exist in our records.

During handling of the above exception, another exception occurred:

Traceback (most recent call last):
  File "/home/airflow/.local/lib/python3.8/site-packages/airflow/operators/python.py", line 192, in execute
    return_value = self.execute_callable()
  File "/home/airflow/.local/lib/python3.8/site-packages/airflow/operators/python.py", line 209, in execute_callable
    return self.python_callable(*self.op_args, **self.op_kwargs)
  File "/opt/airflow/dags/s3_upload_dag.py", line 17, in upload_file
    client.upload_file('/opt/airflow/files/organizations_500000.csv', 'sarthak-aws-bucket-003', 'Organizations-file')
  File "/home/airflow/.local/lib/python3.8/site-packages/boto3/s3/inject.py", line 143, in upload_file
    return transfer.upload_file(
  File "/home/airflow/.local/lib/python3.8/site-packages/boto3/s3/transfer.py", line 298, in upload_file
    raise S3UploadFailedError(
boto3.exceptions.S3UploadFailedError: Failed to upload /opt/***/files/organizations_500000.csv to sarthak-aws-bucket-003/Organizations-file: An error occurred (InvalidAccessKeyId) when calling the CreateMultipartUpload operation: The AWS Access Key Id you provided does not exist in our records.
[2023-12-11T18:20:46.651+0000] {taskinstance.py:1400} INFO - Marking task as FAILED. dag_id=s3_upload, task_id=s3_file_upload, execution_date=20231211T182023, start_date=20231211T182045, end_date=20231211T182046
[2023-12-11T18:20:46.665+0000] {standard_task_runner.py:104} ERROR - Failed to execute job 13 for task s3_file_upload (Failed to upload /opt/***/files/organizations_500000.csv to sarthak-aws-bucket-003/Organizations-file: An error occurred (InvalidAccessKeyId) when calling the CreateMultipartUpload operation: The AWS Access Key Id you provided does not exist in our records.; 1859)
[2023-12-11T18:20:46.699+0000] {local_task_job_runner.py:228} INFO - Task exited with return code 1
[2023-12-11T18:20:46.715+0000] {taskinstance.py:2778} INFO - 0 downstream tasks scheduled from follow-on schedule check
