[2023-12-11T08:55:43.254+0000] {taskinstance.py:1159} INFO - Dependencies all met for dep_context=non-requeueable deps ti=<TaskInstance: s3_upload.upload_file manual__2023-12-11T08:55:33.993390+00:00 [queued]>
[2023-12-11T08:55:43.258+0000] {taskinstance.py:1159} INFO - Dependencies all met for dep_context=requeueable deps ti=<TaskInstance: s3_upload.upload_file manual__2023-12-11T08:55:33.993390+00:00 [queued]>
[2023-12-11T08:55:43.258+0000] {taskinstance.py:1361} INFO - Starting attempt 2 of 4
[2023-12-11T08:55:43.264+0000] {taskinstance.py:1382} INFO - Executing <Task(PythonOperator): upload_file> on 2023-12-11 08:55:33.993390+00:00
[2023-12-11T08:55:43.267+0000] {standard_task_runner.py:57} INFO - Started process 493 to run task
[2023-12-11T08:55:43.269+0000] {standard_task_runner.py:84} INFO - Running: ['***', 'tasks', 'run', 's3_upload', 'upload_file', 'manual__2023-12-11T08:55:33.993390+00:00', '--job-id', '20', '--raw', '--subdir', 'DAGS_FOLDER/s3_upload_dag.py', '--cfg-path', '/tmp/tmp0xbye6ky']
[2023-12-11T08:55:43.271+0000] {standard_task_runner.py:85} INFO - Job 20: Subtask upload_file
[2023-12-11T08:55:43.293+0000] {task_command.py:416} INFO - Running <TaskInstance: s3_upload.upload_file manual__2023-12-11T08:55:33.993390+00:00 [running]> on host d2ff3e8f0ec4
[2023-12-11T08:55:43.327+0000] {taskinstance.py:1662} INFO - Exporting env vars: AIRFLOW_CTX_DAG_OWNER='sarthak' AIRFLOW_CTX_DAG_ID='s3_upload' AIRFLOW_CTX_TASK_ID='upload_file' AIRFLOW_CTX_EXECUTION_DATE='2023-12-11T08:55:33.993390+00:00' AIRFLOW_CTX_TRY_NUMBER='2' AIRFLOW_CTX_DAG_RUN_ID='manual__2023-12-11T08:55:33.993390+00:00'
[2023-12-11T08:55:43.459+0000] {taskinstance.py:1937} ERROR - Task failed with exception
Traceback (most recent call last):
  File "/home/airflow/.local/lib/python3.8/site-packages/airflow/operators/python.py", line 192, in execute
    return_value = self.execute_callable()
  File "/home/airflow/.local/lib/python3.8/site-packages/airflow/operators/python.py", line 209, in execute_callable
    return self.python_callable(*self.op_args, **self.op_kwargs)
  File "/opt/airflow/dags/s3_upload_dag.py", line 14, in upload_file
    client.upload_file('opt/files/organizations_500000.csv', 'my-bucket-sarthak-002', 'Organizations-file')
  File "/home/airflow/.local/lib/python3.8/site-packages/boto3/s3/inject.py", line 143, in upload_file
    return transfer.upload_file(
  File "/home/airflow/.local/lib/python3.8/site-packages/boto3/s3/transfer.py", line 292, in upload_file
    future.result()
  File "/home/airflow/.local/lib/python3.8/site-packages/s3transfer/futures.py", line 103, in result
    return self._coordinator.result()
  File "/home/airflow/.local/lib/python3.8/site-packages/s3transfer/futures.py", line 266, in result
    raise self._exception
  File "/home/airflow/.local/lib/python3.8/site-packages/s3transfer/tasks.py", line 269, in _main
    self._submit(transfer_future=transfer_future, **kwargs)
  File "/home/airflow/.local/lib/python3.8/site-packages/s3transfer/upload.py", line 591, in _submit
    upload_input_manager.provide_transfer_size(transfer_future)
  File "/home/airflow/.local/lib/python3.8/site-packages/s3transfer/upload.py", line 244, in provide_transfer_size
    self._osutil.get_file_size(transfer_future.meta.call_args.fileobj)
  File "/home/airflow/.local/lib/python3.8/site-packages/s3transfer/utils.py", line 247, in get_file_size
    return os.path.getsize(filename)
  File "/usr/local/lib/python3.8/genericpath.py", line 50, in getsize
    return os.stat(filename).st_size
FileNotFoundError: [Errno 2] No such file or directory: 'opt/files/organizations_500000.csv'
[2023-12-11T08:55:43.464+0000] {taskinstance.py:1400} INFO - Marking task as UP_FOR_RETRY. dag_id=s3_upload, task_id=upload_file, execution_date=20231211T085533, start_date=20231211T085543, end_date=20231211T085543
[2023-12-11T08:55:43.469+0000] {standard_task_runner.py:104} ERROR - Failed to execute job 20 for task upload_file ([Errno 2] No such file or directory: 'opt/files/organizations_500000.csv'; 493)
[2023-12-11T08:55:43.486+0000] {local_task_job_runner.py:228} INFO - Task exited with return code 1
[2023-12-11T08:55:43.494+0000] {taskinstance.py:2778} INFO - 0 downstream tasks scheduled from follow-on schedule check
