[2023-12-11T00:47:01.521+0000] {taskinstance.py:1159} INFO - Dependencies all met for dep_context=non-requeueable deps ti=<TaskInstance: s3_upload.upload_file scheduled__2023-12-10T00:00:00+00:00 [queued]>
[2023-12-11T00:47:01.543+0000] {taskinstance.py:1159} INFO - Dependencies all met for dep_context=requeueable deps ti=<TaskInstance: s3_upload.upload_file scheduled__2023-12-10T00:00:00+00:00 [queued]>
[2023-12-11T00:47:01.544+0000] {taskinstance.py:1361} INFO - Starting attempt 1 of 4
[2023-12-11T00:47:01.577+0000] {taskinstance.py:1382} INFO - Executing <Task(PythonOperator): upload_file> on 2023-12-10 00:00:00+00:00
[2023-12-11T00:47:01.585+0000] {standard_task_runner.py:57} INFO - Started process 1026 to run task
[2023-12-11T00:47:01.616+0000] {standard_task_runner.py:84} INFO - Running: ['***', 'tasks', 'run', 's3_upload', 'upload_file', 'scheduled__2023-12-10T00:00:00+00:00', '--job-id', '15', '--raw', '--subdir', 'DAGS_FOLDER/s3_upload_dag.py', '--cfg-path', '/tmp/tmpb46csv8i']
[2023-12-11T00:47:01.623+0000] {standard_task_runner.py:85} INFO - Job 15: Subtask upload_file
[2023-12-11T00:47:01.753+0000] {task_command.py:416} INFO - Running <TaskInstance: s3_upload.upload_file scheduled__2023-12-10T00:00:00+00:00 [running]> on host 524aa457b57f
[2023-12-11T00:47:01.887+0000] {taskinstance.py:1662} INFO - Exporting env vars: AIRFLOW_CTX_DAG_OWNER='sarthak' AIRFLOW_CTX_DAG_ID='s3_upload' AIRFLOW_CTX_TASK_ID='upload_file' AIRFLOW_CTX_EXECUTION_DATE='2023-12-10T00:00:00+00:00' AIRFLOW_CTX_TRY_NUMBER='1' AIRFLOW_CTX_DAG_RUN_ID='scheduled__2023-12-10T00:00:00+00:00'
[2023-12-11T00:47:02.366+0000] {taskinstance.py:1937} ERROR - Task failed with exception
Traceback (most recent call last):
  File "/home/airflow/.local/lib/python3.8/site-packages/airflow/operators/python.py", line 192, in execute
    return_value = self.execute_callable()
  File "/home/airflow/.local/lib/python3.8/site-packages/airflow/operators/python.py", line 209, in execute_callable
    return self.python_callable(*self.op_args, **self.op_kwargs)
  File "/opt/airflow/dags/s3_upload_dag.py", line 14, in upload_file
    client.upload_file('/Users/sarthakgarg/Downloads/organizations-500000.csv', 'my-bucket-sarthak-002', 'Organizations-file')
  File "/home/airflow/.local/lib/python3.8/site-packages/boto3/s3/inject.py", line 143, in upload_file
    return transfer.upload_file(
  File "/home/airflow/.local/lib/python3.8/site-packages/boto3/s3/transfer.py", line 292, in upload_file
    future.result()
  File "/home/airflow/.local/lib/python3.8/site-packages/s3transfer/futures.py", line 103, in result
    return self._coordinator.result()
  File "/home/airflow/.local/lib/python3.8/site-packages/s3transfer/futures.py", line 266, in result
    raise self._exception
  File "/home/airflow/.local/lib/python3.8/site-packages/s3transfer/tasks.py", line 269, in _main
    self._submit(transfer_future=transfer_future, **kwargs)
  File "/home/airflow/.local/lib/python3.8/site-packages/s3transfer/upload.py", line 591, in _submit
    upload_input_manager.provide_transfer_size(transfer_future)
  File "/home/airflow/.local/lib/python3.8/site-packages/s3transfer/upload.py", line 244, in provide_transfer_size
    self._osutil.get_file_size(transfer_future.meta.call_args.fileobj)
  File "/home/airflow/.local/lib/python3.8/site-packages/s3transfer/utils.py", line 247, in get_file_size
    return os.path.getsize(filename)
  File "/usr/local/lib/python3.8/genericpath.py", line 50, in getsize
    return os.stat(filename).st_size
FileNotFoundError: [Errno 2] No such file or directory: '/Users/sarthakgarg/Downloads/organizations-500000.csv'
[2023-12-11T00:47:02.390+0000] {taskinstance.py:1400} INFO - Marking task as UP_FOR_RETRY. dag_id=s3_upload, task_id=upload_file, execution_date=20231210T000000, start_date=20231211T004701, end_date=20231211T004702
[2023-12-11T00:47:02.417+0000] {standard_task_runner.py:104} ERROR - Failed to execute job 15 for task upload_file ([Errno 2] No such file or directory: '/Users/sarthakgarg/Downloads/organizations-500000.csv'; 1026)
[2023-12-11T00:47:02.448+0000] {local_task_job_runner.py:228} INFO - Task exited with return code 1
[2023-12-11T00:47:02.477+0000] {taskinstance.py:2778} INFO - 0 downstream tasks scheduled from follow-on schedule check
[2023-12-11T04:14:39.378+0000] {taskinstance.py:1159} INFO - Dependencies all met for dep_context=non-requeueable deps ti=<TaskInstance: s3_upload.upload_file scheduled__2023-12-10T00:00:00+00:00 [queued]>
[2023-12-11T04:14:39.383+0000] {taskinstance.py:1159} INFO - Dependencies all met for dep_context=requeueable deps ti=<TaskInstance: s3_upload.upload_file scheduled__2023-12-10T00:00:00+00:00 [queued]>
[2023-12-11T04:14:39.383+0000] {taskinstance.py:1361} INFO - Starting attempt 1 of 4
[2023-12-11T04:14:39.391+0000] {taskinstance.py:1382} INFO - Executing <Task(PythonOperator): upload_file> on 2023-12-10 00:00:00+00:00
[2023-12-11T04:14:39.394+0000] {standard_task_runner.py:57} INFO - Started process 181 to run task
[2023-12-11T04:14:39.397+0000] {standard_task_runner.py:84} INFO - Running: ['***', 'tasks', 'run', 's3_upload', 'upload_file', 'scheduled__2023-12-10T00:00:00+00:00', '--job-id', '3', '--raw', '--subdir', 'DAGS_FOLDER/s3_upload_dag.py', '--cfg-path', '/tmp/tmpk1bz2y28']
[2023-12-11T04:14:39.399+0000] {standard_task_runner.py:85} INFO - Job 3: Subtask upload_file
[2023-12-11T04:14:39.430+0000] {task_command.py:416} INFO - Running <TaskInstance: s3_upload.upload_file scheduled__2023-12-10T00:00:00+00:00 [running]> on host 900665ffa878
[2023-12-11T04:14:39.472+0000] {taskinstance.py:1662} INFO - Exporting env vars: AIRFLOW_CTX_DAG_OWNER='sarthak' AIRFLOW_CTX_DAG_ID='s3_upload' AIRFLOW_CTX_TASK_ID='upload_file' AIRFLOW_CTX_EXECUTION_DATE='2023-12-10T00:00:00+00:00' AIRFLOW_CTX_TRY_NUMBER='1' AIRFLOW_CTX_DAG_RUN_ID='scheduled__2023-12-10T00:00:00+00:00'
[2023-12-11T04:14:39.720+0000] {taskinstance.py:1937} ERROR - Task failed with exception
Traceback (most recent call last):
  File "/home/airflow/.local/lib/python3.8/site-packages/airflow/operators/python.py", line 192, in execute
    return_value = self.execute_callable()
  File "/home/airflow/.local/lib/python3.8/site-packages/airflow/operators/python.py", line 209, in execute_callable
    return self.python_callable(*self.op_args, **self.op_kwargs)
  File "/opt/airflow/dags/s3_upload_dag.py", line 14, in upload_file
    client.upload_file('/opt/airflow/downloads/organizations-500000.csv', 'my-bucket-sarthak-002', 'Organizations-file')
  File "/home/airflow/.local/lib/python3.8/site-packages/boto3/s3/inject.py", line 143, in upload_file
    return transfer.upload_file(
  File "/home/airflow/.local/lib/python3.8/site-packages/boto3/s3/transfer.py", line 292, in upload_file
    future.result()
  File "/home/airflow/.local/lib/python3.8/site-packages/s3transfer/futures.py", line 103, in result
    return self._coordinator.result()
  File "/home/airflow/.local/lib/python3.8/site-packages/s3transfer/futures.py", line 266, in result
    raise self._exception
  File "/home/airflow/.local/lib/python3.8/site-packages/s3transfer/tasks.py", line 139, in __call__
    return self._execute_main(kwargs)
  File "/home/airflow/.local/lib/python3.8/site-packages/s3transfer/tasks.py", line 162, in _execute_main
    return_value = self._main(**kwargs)
  File "/home/airflow/.local/lib/python3.8/site-packages/s3transfer/tasks.py", line 348, in _main
    response = client.create_multipart_upload(
  File "/home/airflow/.local/lib/python3.8/site-packages/botocore/client.py", line 535, in _api_call
    return self._make_api_call(operation_name, kwargs)
  File "/home/airflow/.local/lib/python3.8/site-packages/botocore/client.py", line 963, in _make_api_call
    http, parsed_response = self._make_request(
  File "/home/airflow/.local/lib/python3.8/site-packages/botocore/client.py", line 986, in _make_request
    return self._endpoint.make_request(operation_model, request_dict)
  File "/home/airflow/.local/lib/python3.8/site-packages/botocore/endpoint.py", line 119, in make_request
    return self._send_request(request_dict, operation_model)
  File "/home/airflow/.local/lib/python3.8/site-packages/botocore/endpoint.py", line 198, in _send_request
    request = self.create_request(request_dict, operation_model)
  File "/home/airflow/.local/lib/python3.8/site-packages/botocore/endpoint.py", line 134, in create_request
    self._event_emitter.emit(
  File "/home/airflow/.local/lib/python3.8/site-packages/botocore/hooks.py", line 412, in emit
    return self._emitter.emit(aliased_event_name, **kwargs)
  File "/home/airflow/.local/lib/python3.8/site-packages/botocore/hooks.py", line 256, in emit
    return self._emit(event_name, kwargs)
  File "/home/airflow/.local/lib/python3.8/site-packages/botocore/hooks.py", line 239, in _emit
    response = handler(**kwargs)
  File "/home/airflow/.local/lib/python3.8/site-packages/botocore/signers.py", line 105, in handler
    return self.sign(operation_name, request)
  File "/home/airflow/.local/lib/python3.8/site-packages/botocore/signers.py", line 189, in sign
    auth.add_auth(request)
  File "/home/airflow/.local/lib/python3.8/site-packages/botocore/auth.py", line 418, in add_auth
    raise NoCredentialsError()
botocore.exceptions.NoCredentialsError: Unable to locate credentials
[2023-12-11T04:14:39.727+0000] {taskinstance.py:1400} INFO - Marking task as UP_FOR_RETRY. dag_id=s3_upload, task_id=upload_file, execution_date=20231210T000000, start_date=20231211T041439, end_date=20231211T041439
[2023-12-11T04:14:39.732+0000] {standard_task_runner.py:104} ERROR - Failed to execute job 3 for task upload_file (Unable to locate credentials; 181)
[2023-12-11T04:14:39.777+0000] {local_task_job_runner.py:228} INFO - Task exited with return code 1
[2023-12-11T04:14:39.787+0000] {taskinstance.py:2778} INFO - 0 downstream tasks scheduled from follow-on schedule check
[2023-12-11T08:45:02.286+0000] {taskinstance.py:1159} INFO - Dependencies all met for dep_context=non-requeueable deps ti=<TaskInstance: s3_upload.upload_file scheduled__2023-12-10T00:00:00+00:00 [queued]>
[2023-12-11T08:45:02.292+0000] {taskinstance.py:1159} INFO - Dependencies all met for dep_context=requeueable deps ti=<TaskInstance: s3_upload.upload_file scheduled__2023-12-10T00:00:00+00:00 [queued]>
[2023-12-11T08:45:02.292+0000] {taskinstance.py:1361} INFO - Starting attempt 1 of 4
[2023-12-11T08:45:02.300+0000] {taskinstance.py:1382} INFO - Executing <Task(PythonOperator): upload_file> on 2023-12-10 00:00:00+00:00
[2023-12-11T08:45:02.304+0000] {standard_task_runner.py:57} INFO - Started process 186 to run task
[2023-12-11T08:45:02.307+0000] {standard_task_runner.py:84} INFO - Running: ['***', 'tasks', 'run', 's3_upload', 'upload_file', 'scheduled__2023-12-10T00:00:00+00:00', '--job-id', '3', '--raw', '--subdir', 'DAGS_FOLDER/s3_upload_dag.py', '--cfg-path', '/tmp/tmp78d72hwv']
[2023-12-11T08:45:02.309+0000] {standard_task_runner.py:85} INFO - Job 3: Subtask upload_file
[2023-12-11T08:45:02.340+0000] {task_command.py:416} INFO - Running <TaskInstance: s3_upload.upload_file scheduled__2023-12-10T00:00:00+00:00 [running]> on host d2ff3e8f0ec4
[2023-12-11T08:45:02.383+0000] {taskinstance.py:1662} INFO - Exporting env vars: AIRFLOW_CTX_DAG_OWNER='sarthak' AIRFLOW_CTX_DAG_ID='s3_upload' AIRFLOW_CTX_TASK_ID='upload_file' AIRFLOW_CTX_EXECUTION_DATE='2023-12-10T00:00:00+00:00' AIRFLOW_CTX_TRY_NUMBER='1' AIRFLOW_CTX_DAG_RUN_ID='scheduled__2023-12-10T00:00:00+00:00'
[2023-12-11T08:45:04.724+0000] {taskinstance.py:1937} ERROR - Task failed with exception
Traceback (most recent call last):
  File "/home/airflow/.local/lib/python3.8/site-packages/airflow/operators/python.py", line 192, in execute
    return_value = self.execute_callable()
  File "/home/airflow/.local/lib/python3.8/site-packages/airflow/operators/python.py", line 209, in execute_callable
    return self.python_callable(*self.op_args, **self.op_kwargs)
  File "/opt/airflow/dags/s3_upload_dag.py", line 14, in upload_file
    client.upload_file('~/files/organizations-500000.csv', 'my-bucket-sarthak-002', 'Organizations-file')
  File "/home/airflow/.local/lib/python3.8/site-packages/boto3/s3/inject.py", line 143, in upload_file
    return transfer.upload_file(
  File "/home/airflow/.local/lib/python3.8/site-packages/boto3/s3/transfer.py", line 292, in upload_file
    future.result()
  File "/home/airflow/.local/lib/python3.8/site-packages/s3transfer/futures.py", line 103, in result
    return self._coordinator.result()
  File "/home/airflow/.local/lib/python3.8/site-packages/s3transfer/futures.py", line 266, in result
    raise self._exception
  File "/home/airflow/.local/lib/python3.8/site-packages/s3transfer/tasks.py", line 269, in _main
    self._submit(transfer_future=transfer_future, **kwargs)
  File "/home/airflow/.local/lib/python3.8/site-packages/s3transfer/upload.py", line 591, in _submit
    upload_input_manager.provide_transfer_size(transfer_future)
  File "/home/airflow/.local/lib/python3.8/site-packages/s3transfer/upload.py", line 244, in provide_transfer_size
    self._osutil.get_file_size(transfer_future.meta.call_args.fileobj)
  File "/home/airflow/.local/lib/python3.8/site-packages/s3transfer/utils.py", line 247, in get_file_size
    return os.path.getsize(filename)
  File "/usr/local/lib/python3.8/genericpath.py", line 50, in getsize
    return os.stat(filename).st_size
FileNotFoundError: [Errno 2] No such file or directory: '~/files/organizations-500000.csv'
[2023-12-11T08:45:04.742+0000] {taskinstance.py:1400} INFO - Marking task as UP_FOR_RETRY. dag_id=s3_upload, task_id=upload_file, execution_date=20231210T000000, start_date=20231211T084502, end_date=20231211T084504
[2023-12-11T08:45:04.752+0000] {standard_task_runner.py:104} ERROR - Failed to execute job 3 for task upload_file ([Errno 2] No such file or directory: '~/files/organizations-500000.csv'; 186)
[2023-12-11T08:45:04.786+0000] {local_task_job_runner.py:228} INFO - Task exited with return code 1
[2023-12-11T08:45:04.797+0000] {taskinstance.py:2778} INFO - 0 downstream tasks scheduled from follow-on schedule check
[2023-12-11T09:34:08.343+0000] {taskinstance.py:1159} INFO - Dependencies all met for dep_context=non-requeueable deps ti=<TaskInstance: s3_upload.upload_file scheduled__2023-12-10T00:00:00+00:00 [queued]>
[2023-12-11T09:34:08.347+0000] {taskinstance.py:1159} INFO - Dependencies all met for dep_context=requeueable deps ti=<TaskInstance: s3_upload.upload_file scheduled__2023-12-10T00:00:00+00:00 [queued]>
[2023-12-11T09:34:08.347+0000] {taskinstance.py:1361} INFO - Starting attempt 1 of 4
[2023-12-11T09:34:08.353+0000] {taskinstance.py:1382} INFO - Executing <Task(PythonOperator): upload_file> on 2023-12-10 00:00:00+00:00
[2023-12-11T09:34:08.357+0000] {standard_task_runner.py:57} INFO - Started process 181 to run task
[2023-12-11T09:34:08.359+0000] {standard_task_runner.py:84} INFO - Running: ['***', 'tasks', 'run', 's3_upload', 'upload_file', 'scheduled__2023-12-10T00:00:00+00:00', '--job-id', '3', '--raw', '--subdir', 'DAGS_FOLDER/s3_upload_dag.py', '--cfg-path', '/tmp/tmpzb6sswbf']
[2023-12-11T09:34:08.360+0000] {standard_task_runner.py:85} INFO - Job 3: Subtask upload_file
[2023-12-11T09:34:08.386+0000] {task_command.py:416} INFO - Running <TaskInstance: s3_upload.upload_file scheduled__2023-12-10T00:00:00+00:00 [running]> on host 926eb853a40f
[2023-12-11T09:34:08.425+0000] {taskinstance.py:1662} INFO - Exporting env vars: AIRFLOW_CTX_DAG_OWNER='sarthak' AIRFLOW_CTX_DAG_ID='s3_upload' AIRFLOW_CTX_TASK_ID='upload_file' AIRFLOW_CTX_EXECUTION_DATE='2023-12-10T00:00:00+00:00' AIRFLOW_CTX_TRY_NUMBER='1' AIRFLOW_CTX_DAG_RUN_ID='scheduled__2023-12-10T00:00:00+00:00'
[2023-12-11T09:34:10.891+0000] {taskinstance.py:1937} ERROR - Task failed with exception
Traceback (most recent call last):
  File "/home/airflow/.local/lib/python3.8/site-packages/airflow/operators/python.py", line 192, in execute
    return_value = self.execute_callable()
  File "/home/airflow/.local/lib/python3.8/site-packages/airflow/operators/python.py", line 209, in execute_callable
    return self.python_callable(*self.op_args, **self.op_kwargs)
  File "/opt/airflow/dags/s3_upload_dag.py", line 14, in upload_file
    client.upload_file('opt/airflow/files/organizations_500000.csv', 'sarthak-aws-bucket-002', 'Organizations-file')
  File "/home/airflow/.local/lib/python3.8/site-packages/boto3/s3/inject.py", line 143, in upload_file
    return transfer.upload_file(
  File "/home/airflow/.local/lib/python3.8/site-packages/boto3/s3/transfer.py", line 292, in upload_file
    future.result()
  File "/home/airflow/.local/lib/python3.8/site-packages/s3transfer/futures.py", line 103, in result
    return self._coordinator.result()
  File "/home/airflow/.local/lib/python3.8/site-packages/s3transfer/futures.py", line 266, in result
    raise self._exception
  File "/home/airflow/.local/lib/python3.8/site-packages/s3transfer/tasks.py", line 269, in _main
    self._submit(transfer_future=transfer_future, **kwargs)
  File "/home/airflow/.local/lib/python3.8/site-packages/s3transfer/upload.py", line 591, in _submit
    upload_input_manager.provide_transfer_size(transfer_future)
  File "/home/airflow/.local/lib/python3.8/site-packages/s3transfer/upload.py", line 244, in provide_transfer_size
    self._osutil.get_file_size(transfer_future.meta.call_args.fileobj)
  File "/home/airflow/.local/lib/python3.8/site-packages/s3transfer/utils.py", line 247, in get_file_size
    return os.path.getsize(filename)
  File "/usr/local/lib/python3.8/genericpath.py", line 50, in getsize
    return os.stat(filename).st_size
FileNotFoundError: [Errno 2] No such file or directory: 'opt/airflow/files/organizations_500000.csv'
[2023-12-11T09:34:10.902+0000] {taskinstance.py:1400} INFO - Marking task as UP_FOR_RETRY. dag_id=s3_upload, task_id=upload_file, execution_date=20231210T000000, start_date=20231211T093408, end_date=20231211T093410
[2023-12-11T09:34:10.913+0000] {standard_task_runner.py:104} ERROR - Failed to execute job 3 for task upload_file ([Errno 2] No such file or directory: 'opt/airflow/files/organizations_500000.csv'; 181)
[2023-12-11T09:34:10.940+0000] {local_task_job_runner.py:228} INFO - Task exited with return code 1
[2023-12-11T09:34:10.975+0000] {taskinstance.py:2778} INFO - 0 downstream tasks scheduled from follow-on schedule check
[2023-12-11T09:38:08.825+0000] {taskinstance.py:1159} INFO - Dependencies all met for dep_context=non-requeueable deps ti=<TaskInstance: s3_upload.upload_file scheduled__2023-12-10T00:00:00+00:00 [queued]>
[2023-12-11T09:38:08.830+0000] {taskinstance.py:1159} INFO - Dependencies all met for dep_context=requeueable deps ti=<TaskInstance: s3_upload.upload_file scheduled__2023-12-10T00:00:00+00:00 [queued]>
[2023-12-11T09:38:08.830+0000] {taskinstance.py:1361} INFO - Starting attempt 1 of 4
[2023-12-11T09:38:08.837+0000] {taskinstance.py:1382} INFO - Executing <Task(PythonOperator): upload_file> on 2023-12-10 00:00:00+00:00
[2023-12-11T09:38:08.841+0000] {standard_task_runner.py:57} INFO - Started process 173 to run task
[2023-12-11T09:38:08.844+0000] {standard_task_runner.py:84} INFO - Running: ['***', 'tasks', 'run', 's3_upload', 'upload_file', 'scheduled__2023-12-10T00:00:00+00:00', '--job-id', '3', '--raw', '--subdir', 'DAGS_FOLDER/s3_upload_dag.py', '--cfg-path', '/tmp/tmpzsw8xtxg']
[2023-12-11T09:38:08.846+0000] {standard_task_runner.py:85} INFO - Job 3: Subtask upload_file
[2023-12-11T09:38:08.879+0000] {task_command.py:416} INFO - Running <TaskInstance: s3_upload.upload_file scheduled__2023-12-10T00:00:00+00:00 [running]> on host 9ddc40d2249c
[2023-12-11T09:38:08.942+0000] {taskinstance.py:1662} INFO - Exporting env vars: AIRFLOW_CTX_DAG_OWNER='sarthak' AIRFLOW_CTX_DAG_ID='s3_upload' AIRFLOW_CTX_TASK_ID='upload_file' AIRFLOW_CTX_EXECUTION_DATE='2023-12-10T00:00:00+00:00' AIRFLOW_CTX_TRY_NUMBER='1' AIRFLOW_CTX_DAG_RUN_ID='scheduled__2023-12-10T00:00:00+00:00'
[2023-12-11T09:38:10.365+0000] {taskinstance.py:1937} ERROR - Task failed with exception
Traceback (most recent call last):
  File "/home/airflow/.local/lib/python3.8/site-packages/airflow/operators/python.py", line 192, in execute
    return_value = self.execute_callable()
  File "/home/airflow/.local/lib/python3.8/site-packages/airflow/operators/python.py", line 209, in execute_callable
    return self.python_callable(*self.op_args, **self.op_kwargs)
  File "/opt/airflow/dags/s3_upload_dag.py", line 14, in upload_file
    client.upload_file('opt/airflow/files/organizations_500000.csv', 'sarthak-aws-bucket-002', 'Organizations-file')
  File "/home/airflow/.local/lib/python3.8/site-packages/boto3/s3/inject.py", line 143, in upload_file
    return transfer.upload_file(
  File "/home/airflow/.local/lib/python3.8/site-packages/boto3/s3/transfer.py", line 292, in upload_file
    future.result()
  File "/home/airflow/.local/lib/python3.8/site-packages/s3transfer/futures.py", line 103, in result
    return self._coordinator.result()
  File "/home/airflow/.local/lib/python3.8/site-packages/s3transfer/futures.py", line 266, in result
    raise self._exception
  File "/home/airflow/.local/lib/python3.8/site-packages/s3transfer/tasks.py", line 269, in _main
    self._submit(transfer_future=transfer_future, **kwargs)
  File "/home/airflow/.local/lib/python3.8/site-packages/s3transfer/upload.py", line 591, in _submit
    upload_input_manager.provide_transfer_size(transfer_future)
  File "/home/airflow/.local/lib/python3.8/site-packages/s3transfer/upload.py", line 244, in provide_transfer_size
    self._osutil.get_file_size(transfer_future.meta.call_args.fileobj)
  File "/home/airflow/.local/lib/python3.8/site-packages/s3transfer/utils.py", line 247, in get_file_size
    return os.path.getsize(filename)
  File "/usr/local/lib/python3.8/genericpath.py", line 50, in getsize
    return os.stat(filename).st_size
FileNotFoundError: [Errno 2] No such file or directory: 'opt/airflow/files/organizations_500000.csv'
[2023-12-11T09:38:10.373+0000] {taskinstance.py:1400} INFO - Marking task as UP_FOR_RETRY. dag_id=s3_upload, task_id=upload_file, execution_date=20231210T000000, start_date=20231211T093808, end_date=20231211T093810
[2023-12-11T09:38:10.380+0000] {standard_task_runner.py:104} ERROR - Failed to execute job 3 for task upload_file ([Errno 2] No such file or directory: 'opt/airflow/files/organizations_500000.csv'; 173)
[2023-12-11T09:38:10.421+0000] {local_task_job_runner.py:228} INFO - Task exited with return code 1
[2023-12-11T09:38:10.459+0000] {taskinstance.py:2778} INFO - 0 downstream tasks scheduled from follow-on schedule check
