[2023-12-12T06:58:19.937+0000] {taskinstance.py:1159} INFO - Dependencies all met for dep_context=non-requeueable deps ti=<TaskInstance: s3_hook_overview.copy_into_command manual__2023-12-12T06:53:13.765563+00:00 [queued]>
[2023-12-12T06:58:19.944+0000] {taskinstance.py:1159} INFO - Dependencies all met for dep_context=requeueable deps ti=<TaskInstance: s3_hook_overview.copy_into_command manual__2023-12-12T06:53:13.765563+00:00 [queued]>
[2023-12-12T06:58:19.945+0000] {taskinstance.py:1361} INFO - Starting attempt 2 of 2
[2023-12-12T06:58:19.954+0000] {taskinstance.py:1382} INFO - Executing <Task(SnowflakeOperator): copy_into_command> on 2023-12-12 06:53:13.765563+00:00
[2023-12-12T06:58:19.960+0000] {standard_task_runner.py:57} INFO - Started process 401 to run task
[2023-12-12T06:58:19.963+0000] {standard_task_runner.py:84} INFO - Running: ['***', 'tasks', 'run', 's3_hook_overview', 'copy_into_command', 'manual__2023-12-12T06:53:13.765563+00:00', '--job-id', '37', '--raw', '--subdir', 'DAGS_FOLDER/load_into_snowflake.py', '--cfg-path', '/tmp/tmpv_yei142']
[2023-12-12T06:58:19.965+0000] {standard_task_runner.py:85} INFO - Job 37: Subtask copy_into_command
[2023-12-12T06:58:19.999+0000] {task_command.py:416} INFO - Running <TaskInstance: s3_hook_overview.copy_into_command manual__2023-12-12T06:53:13.765563+00:00 [running]> on host d50382fa2a13
[2023-12-12T06:58:20.022+0000] {abstractoperator.py:709} ERROR - Exception rendering Jinja template for task 'copy_into_command', field 'sql'. Template: '/opt/***/proj/sql/snowflake_load.sql'
Traceback (most recent call last):
  File "/home/airflow/.local/lib/python3.8/site-packages/airflow/models/abstractoperator.py", line 701, in _do_render_template_fields
    rendered_content = self.render_template(
  File "/home/airflow/.local/lib/python3.8/site-packages/airflow/template/templater.py", line 152, in render_template
    template = jinja_env.get_template(value)
  File "/home/airflow/.local/lib/python3.8/site-packages/jinja2/environment.py", line 1010, in get_template
    return self._load_template(name, globals)
  File "/home/airflow/.local/lib/python3.8/site-packages/jinja2/environment.py", line 969, in _load_template
    template = self.loader.load(self, name, self.make_globals(globals))
  File "/home/airflow/.local/lib/python3.8/site-packages/jinja2/loaders.py", line 126, in load
    source, filename, uptodate = self.get_source(environment, name)
  File "/home/airflow/.local/lib/python3.8/site-packages/jinja2/loaders.py", line 218, in get_source
    raise TemplateNotFound(template)
jinja2.exceptions.TemplateNotFound: /opt/airflow/proj/sql/snowflake_load.sql
[2023-12-12T06:58:20.023+0000] {taskinstance.py:1937} ERROR - Task failed with exception
Traceback (most recent call last):
  File "/home/airflow/.local/lib/python3.8/site-packages/airflow/models/taskinstance.py", line 1518, in _run_raw_task
    self._execute_task_with_callbacks(context, test_mode, session=session)
  File "/home/airflow/.local/lib/python3.8/site-packages/airflow/models/taskinstance.py", line 1647, in _execute_task_with_callbacks
    task_orig = self.render_templates(context=context)
  File "/home/airflow/.local/lib/python3.8/site-packages/airflow/models/taskinstance.py", line 2285, in render_templates
    original_task.render_template_fields(context)
  File "/home/airflow/.local/lib/python3.8/site-packages/airflow/models/baseoperator.py", line 1243, in render_template_fields
    self._do_render_template_fields(self, self.template_fields, context, jinja_env, set())
  File "/home/airflow/.local/lib/python3.8/site-packages/airflow/utils/session.py", line 79, in wrapper
    return func(*args, session=session, **kwargs)
  File "/home/airflow/.local/lib/python3.8/site-packages/airflow/models/abstractoperator.py", line 701, in _do_render_template_fields
    rendered_content = self.render_template(
  File "/home/airflow/.local/lib/python3.8/site-packages/airflow/template/templater.py", line 152, in render_template
    template = jinja_env.get_template(value)
  File "/home/airflow/.local/lib/python3.8/site-packages/jinja2/environment.py", line 1010, in get_template
    return self._load_template(name, globals)
  File "/home/airflow/.local/lib/python3.8/site-packages/jinja2/environment.py", line 969, in _load_template
    template = self.loader.load(self, name, self.make_globals(globals))
  File "/home/airflow/.local/lib/python3.8/site-packages/jinja2/loaders.py", line 126, in load
    source, filename, uptodate = self.get_source(environment, name)
  File "/home/airflow/.local/lib/python3.8/site-packages/jinja2/loaders.py", line 218, in get_source
    raise TemplateNotFound(template)
jinja2.exceptions.TemplateNotFound: /opt/airflow/proj/sql/snowflake_load.sql
[2023-12-12T06:58:20.028+0000] {taskinstance.py:1400} INFO - Marking task as FAILED. dag_id=s3_hook_overview, task_id=copy_into_command, execution_date=20231212T065313, start_date=20231212T065819, end_date=20231212T065820
[2023-12-12T06:58:20.034+0000] {standard_task_runner.py:104} ERROR - Failed to execute job 37 for task copy_into_command (/opt/airflow/proj/sql/snowflake_load.sql; 401)
[2023-12-12T06:58:20.055+0000] {local_task_job_runner.py:228} INFO - Task exited with return code 1
[2023-12-12T06:58:20.064+0000] {taskinstance.py:2778} INFO - 0 downstream tasks scheduled from follow-on schedule check
