[2023-12-14T09:02:01.885+0000] {taskinstance.py:1159} INFO - Dependencies all met for dep_context=non-requeueable deps ti=<TaskInstance: restapi-pipeline.restapi_call_json_data manual__2023-12-14T09:01:33.162215+00:00 [queued]>
[2023-12-14T09:02:01.890+0000] {taskinstance.py:1159} INFO - Dependencies all met for dep_context=requeueable deps ti=<TaskInstance: restapi-pipeline.restapi_call_json_data manual__2023-12-14T09:01:33.162215+00:00 [queued]>
[2023-12-14T09:02:01.890+0000] {taskinstance.py:1361} INFO - Starting attempt 3 of 3
[2023-12-14T09:02:01.896+0000] {taskinstance.py:1382} INFO - Executing <Task(PythonOperator): restapi_call_json_data> on 2023-12-14 09:01:33.162215+00:00
[2023-12-14T09:02:01.901+0000] {standard_task_runner.py:57} INFO - Started process 1377 to run task
[2023-12-14T09:02:01.904+0000] {standard_task_runner.py:84} INFO - Running: ['***', 'tasks', 'run', 'restapi-pipeline', 'restapi_call_json_data', 'manual__2023-12-14T09:01:33.162215+00:00', '--job-id', '121', '--raw', '--subdir', 'DAGS_FOLDER/restapi.py', '--cfg-path', '/tmp/tmpxl9mies5']
[2023-12-14T09:02:01.907+0000] {standard_task_runner.py:85} INFO - Job 121: Subtask restapi_call_json_data
[2023-12-14T09:02:01.959+0000] {task_command.py:416} INFO - Running <TaskInstance: restapi-pipeline.restapi_call_json_data manual__2023-12-14T09:01:33.162215+00:00 [running]> on host b5f695589db2
[2023-12-14T09:02:02.001+0000] {taskinstance.py:1662} INFO - Exporting env vars: AIRFLOW_CTX_DAG_OWNER='sarthak' AIRFLOW_CTX_DAG_ID='restapi-pipeline' AIRFLOW_CTX_TASK_ID='restapi_call_json_data' AIRFLOW_CTX_EXECUTION_DATE='2023-12-14T09:01:33.162215+00:00' AIRFLOW_CTX_TRY_NUMBER='3' AIRFLOW_CTX_DAG_RUN_ID='manual__2023-12-14T09:01:33.162215+00:00'
[2023-12-14T09:02:03.745+0000] {taskinstance.py:1937} ERROR - Task failed with exception
Traceback (most recent call last):
  File "/home/airflow/.local/lib/python3.8/site-packages/airflow/operators/python.py", line 192, in execute
    return_value = self.execute_callable()
  File "/home/airflow/.local/lib/python3.8/site-packages/airflow/operators/python.py", line 209, in execute_callable
    return self.python_callable(*self.op_args, **self.op_kwargs)
  File "/opt/airflow/dags/restapi.py", line 23, in rest_api_call
    with open("/Users/sarthakgarg/Desktop/Airflow_projects/raw_data/test.json",'w') as json_file:
FileNotFoundError: [Errno 2] No such file or directory: '/Users/sarthakgarg/Desktop/Airflow_projects/raw_data/test.json'
[2023-12-14T09:02:03.764+0000] {taskinstance.py:1400} INFO - Marking task as FAILED. dag_id=restapi-pipeline, task_id=restapi_call_json_data, execution_date=20231214T090133, start_date=20231214T090201, end_date=20231214T090203
[2023-12-14T09:02:03.782+0000] {standard_task_runner.py:104} ERROR - Failed to execute job 121 for task restapi_call_json_data ([Errno 2] No such file or directory: '/Users/sarthakgarg/Desktop/Airflow_projects/raw_data/test.json'; 1377)
[2023-12-14T09:02:03.811+0000] {local_task_job_runner.py:228} INFO - Task exited with return code 1
[2023-12-14T09:02:03.841+0000] {taskinstance.py:2778} INFO - 0 downstream tasks scheduled from follow-on schedule check
