[2023-12-16T02:24:48.636+0000] {taskinstance.py:1159} INFO - Dependencies all met for dep_context=non-requeueable deps ti=<TaskInstance: restapi-pipeline.json_file_upload_s3 scheduled__2023-12-15T00:00:00+00:00 [queued]>
[2023-12-16T02:24:48.641+0000] {taskinstance.py:1159} INFO - Dependencies all met for dep_context=requeueable deps ti=<TaskInstance: restapi-pipeline.json_file_upload_s3 scheduled__2023-12-15T00:00:00+00:00 [queued]>
[2023-12-16T02:24:48.642+0000] {taskinstance.py:1361} INFO - Starting attempt 1 of 3
[2023-12-16T02:24:48.651+0000] {taskinstance.py:1382} INFO - Executing <Task(PythonOperator): json_file_upload_s3> on 2023-12-15 00:00:00+00:00
[2023-12-16T02:24:48.655+0000] {standard_task_runner.py:57} INFO - Started process 6521 to run task
[2023-12-16T02:24:48.658+0000] {standard_task_runner.py:84} INFO - Running: ['***', 'tasks', 'run', 'restapi-pipeline', 'json_file_upload_s3', 'scheduled__2023-12-15T00:00:00+00:00', '--job-id', '254', '--raw', '--subdir', 'DAGS_FOLDER/restapi.py', '--cfg-path', '/tmp/tmpfk3cw2ay']
[2023-12-16T02:24:48.661+0000] {standard_task_runner.py:85} INFO - Job 254: Subtask json_file_upload_s3
[2023-12-16T02:24:48.693+0000] {task_command.py:416} INFO - Running <TaskInstance: restapi-pipeline.json_file_upload_s3 scheduled__2023-12-15T00:00:00+00:00 [running]> on host e65e9d73b232
[2023-12-16T02:24:48.741+0000] {taskinstance.py:1662} INFO - Exporting env vars: AIRFLOW_CTX_DAG_OWNER='sarthak' AIRFLOW_CTX_DAG_ID='restapi-pipeline' AIRFLOW_CTX_TASK_ID='json_file_upload_s3' AIRFLOW_CTX_EXECUTION_DATE='2023-12-15T00:00:00+00:00' AIRFLOW_CTX_TRY_NUMBER='1' AIRFLOW_CTX_DAG_RUN_ID='scheduled__2023-12-15T00:00:00+00:00'
[2023-12-16T02:24:50.163+0000] {taskinstance.py:1937} ERROR - Task failed with exception
Traceback (most recent call last):
  File "/home/airflow/.local/lib/python3.8/site-packages/boto3/s3/transfer.py", line 292, in upload_file
    future.result()
  File "/home/airflow/.local/lib/python3.8/site-packages/s3transfer/futures.py", line 103, in result
    return self._coordinator.result()
  File "/home/airflow/.local/lib/python3.8/site-packages/s3transfer/futures.py", line 266, in result
    raise self._exception
  File "/home/airflow/.local/lib/python3.8/site-packages/s3transfer/tasks.py", line 139, in __call__
    return self._execute_main(kwargs)
  File "/home/airflow/.local/lib/python3.8/site-packages/s3transfer/tasks.py", line 162, in _execute_main
    return_value = self._main(**kwargs)
  File "/home/airflow/.local/lib/python3.8/site-packages/s3transfer/upload.py", line 764, in _main
    client.put_object(Bucket=bucket, Key=key, Body=body, **extra_args)
  File "/home/airflow/.local/lib/python3.8/site-packages/botocore/client.py", line 535, in _api_call
    return self._make_api_call(operation_name, kwargs)
  File "/home/airflow/.local/lib/python3.8/site-packages/botocore/client.py", line 980, in _make_api_call
    raise error_class(parsed_response, operation_name)
botocore.exceptions.ClientError: An error occurred (InvalidAccessKeyId) when calling the PutObject operation: The AWS Access Key Id you provided does not exist in our records.

During handling of the above exception, another exception occurred:

Traceback (most recent call last):
  File "/home/airflow/.local/lib/python3.8/site-packages/airflow/operators/python.py", line 192, in execute
    return_value = self.execute_callable()
  File "/home/airflow/.local/lib/python3.8/site-packages/airflow/operators/python.py", line 209, in execute_callable
    return self.python_callable(*self.op_args, **self.op_kwargs)
  File "/opt/airflow/dags/restapi.py", line 54, in upload_file_json
    client.upload_file('/opt/airflow/files/test.json', 'my-random-bucket-002','coin-price-json')
  File "/home/airflow/.local/lib/python3.8/site-packages/boto3/s3/inject.py", line 143, in upload_file
    return transfer.upload_file(
  File "/home/airflow/.local/lib/python3.8/site-packages/boto3/s3/transfer.py", line 298, in upload_file
    raise S3UploadFailedError(
boto3.exceptions.S3UploadFailedError: Failed to upload /opt/***/files/test.json to my-random-bucket-002/coin-price-json: An error occurred (InvalidAccessKeyId) when calling the PutObject operation: The AWS Access Key Id you provided does not exist in our records.
[2023-12-16T02:24:50.177+0000] {taskinstance.py:1400} INFO - Marking task as UP_FOR_RETRY. dag_id=restapi-pipeline, task_id=json_file_upload_s3, execution_date=20231215T000000, start_date=20231216T022448, end_date=20231216T022450
[2023-12-16T02:24:50.221+0000] {standard_task_runner.py:104} ERROR - Failed to execute job 254 for task json_file_upload_s3 (Failed to upload /opt/***/files/test.json to my-random-bucket-002/coin-price-json: An error occurred (InvalidAccessKeyId) when calling the PutObject operation: The AWS Access Key Id you provided does not exist in our records.; 6521)
[2023-12-16T02:24:50.233+0000] {local_task_job_runner.py:228} INFO - Task exited with return code 1
[2023-12-16T02:24:50.249+0000] {taskinstance.py:2778} INFO - 0 downstream tasks scheduled from follow-on schedule check
