[2023-12-11T20:05:04.903+0000] {taskinstance.py:1159} INFO - Dependencies all met for dep_context=non-requeueable deps ti=<TaskInstance: s3_hook_overview.upload_to_snowflake manual__2023-12-11T20:04:43.195399+00:00 [queued]>
[2023-12-11T20:05:04.907+0000] {taskinstance.py:1159} INFO - Dependencies all met for dep_context=requeueable deps ti=<TaskInstance: s3_hook_overview.upload_to_snowflake manual__2023-12-11T20:04:43.195399+00:00 [queued]>
[2023-12-11T20:05:04.908+0000] {taskinstance.py:1361} INFO - Starting attempt 1 of 2
[2023-12-11T20:05:04.914+0000] {taskinstance.py:1382} INFO - Executing <Task(PythonOperator): upload_to_snowflake> on 2023-12-11 20:04:43.195399+00:00
[2023-12-11T20:05:04.917+0000] {standard_task_runner.py:57} INFO - Started process 5573 to run task
[2023-12-11T20:05:04.920+0000] {standard_task_runner.py:84} INFO - Running: ['***', 'tasks', 'run', 's3_hook_overview', 'upload_to_snowflake', 'manual__2023-12-11T20:04:43.195399+00:00', '--job-id', '34', '--raw', '--subdir', 'DAGS_FOLDER/load_into_snowflake.py', '--cfg-path', '/tmp/tmpyeqjhi_5']
[2023-12-11T20:05:04.923+0000] {standard_task_runner.py:85} INFO - Job 34: Subtask upload_to_snowflake
[2023-12-11T20:05:04.949+0000] {task_command.py:416} INFO - Running <TaskInstance: s3_hook_overview.upload_to_snowflake manual__2023-12-11T20:04:43.195399+00:00 [running]> on host a3992be7c3a0
[2023-12-11T20:05:04.986+0000] {taskinstance.py:1662} INFO - Exporting env vars: AIRFLOW_CTX_DAG_OWNER='***' AIRFLOW_CTX_DAG_ID='s3_hook_overview' AIRFLOW_CTX_TASK_ID='upload_to_snowflake' AIRFLOW_CTX_EXECUTION_DATE='2023-12-11T20:04:43.195399+00:00' AIRFLOW_CTX_TRY_NUMBER='1' AIRFLOW_CTX_DAG_RUN_ID='manual__2023-12-11T20:04:43.195399+00:00'
[2023-12-11T20:05:04.998+0000] {taskinstance.py:1937} ERROR - Task failed with exception
Traceback (most recent call last):
  File "/home/airflow/.local/lib/python3.8/site-packages/airflow/operators/python.py", line 192, in execute
    return_value = self.execute_callable()
  File "/home/airflow/.local/lib/python3.8/site-packages/airflow/operators/python.py", line 209, in execute_callable
    return self.python_callable(*self.op_args, **self.op_kwargs)
  File "/opt/airflow/dags/load_into_snowflake.py", line 169, in upload_to_snowflake
    snowflake_task = CopyFromExternalStageToSnowflakeOperator(
  File "/home/airflow/.local/lib/python3.8/site-packages/airflow/models/baseoperator.py", line 437, in apply_defaults
    result = func(self, **kwargs, default_args=default_args)
  File "/home/airflow/.local/lib/python3.8/site-packages/airflow/providers/snowflake/transfers/copy_into_snowflake.py", line 92, in __init__
    super().__init__(**kwargs)
  File "/home/airflow/.local/lib/python3.8/site-packages/airflow/models/baseoperator.py", line 437, in apply_defaults
    result = func(self, **kwargs, default_args=default_args)
  File "/home/airflow/.local/lib/python3.8/site-packages/airflow/models/baseoperator.py", line 794, in __init__
    raise AirflowException(
airflow.exceptions.AirflowException: Invalid arguments were passed to CopyFromExternalStageToSnowflakeOperator (task_id: upload_to_snowflake). Invalid arguments were:
**kwargs: {'s3_bucket': 'sarthak-aws-bucket-003', 's3_key': 'Organizations-file'}
[2023-12-11T20:05:05.001+0000] {taskinstance.py:1400} INFO - Marking task as UP_FOR_RETRY. dag_id=s3_hook_overview, task_id=upload_to_snowflake, execution_date=20231211T200443, start_date=20231211T200504, end_date=20231211T200505
[2023-12-11T20:05:05.005+0000] {standard_task_runner.py:104} ERROR - Failed to execute job 34 for task upload_to_snowflake (Invalid arguments were passed to CopyFromExternalStageToSnowflakeOperator (task_id: upload_to_snowflake). Invalid arguments were:
**kwargs: {'s3_bucket': 'sarthak-aws-bucket-003', 's3_key': 'Organizations-file'}; 5573)
[2023-12-11T20:05:05.012+0000] {local_task_job_runner.py:228} INFO - Task exited with return code 1
[2023-12-11T20:05:05.021+0000] {taskinstance.py:2778} INFO - 0 downstream tasks scheduled from follow-on schedule check
