[2023-12-14T02:01:43.067+0000] {taskinstance.py:1159} INFO - Dependencies all met for dep_context=non-requeueable deps ti=<TaskInstance: s3_hook_overview.download_from_s3 scheduled__2023-12-13T00:00:00+00:00 [queued]>
[2023-12-14T02:01:43.071+0000] {taskinstance.py:1159} INFO - Dependencies all met for dep_context=requeueable deps ti=<TaskInstance: s3_hook_overview.download_from_s3 scheduled__2023-12-13T00:00:00+00:00 [queued]>
[2023-12-14T02:01:43.072+0000] {taskinstance.py:1361} INFO - Starting attempt 2 of 2
[2023-12-14T02:01:43.077+0000] {taskinstance.py:1382} INFO - Executing <Task(PythonOperator): download_from_s3> on 2023-12-13 00:00:00+00:00
[2023-12-14T02:01:43.083+0000] {standard_task_runner.py:57} INFO - Started process 4217 to run task
[2023-12-14T02:01:43.086+0000] {standard_task_runner.py:84} INFO - Running: ['***', 'tasks', 'run', 's3_hook_overview', 'download_from_s3', 'scheduled__2023-12-13T00:00:00+00:00', '--job-id', '91', '--raw', '--subdir', 'DAGS_FOLDER/load_into_snowflake.py', '--cfg-path', '/tmp/tmp44juan_3']
[2023-12-14T02:01:43.089+0000] {standard_task_runner.py:85} INFO - Job 91: Subtask download_from_s3
[2023-12-14T02:01:43.117+0000] {task_command.py:416} INFO - Running <TaskInstance: s3_hook_overview.download_from_s3 scheduled__2023-12-13T00:00:00+00:00 [running]> on host d7c15f19afb2
[2023-12-14T02:01:43.167+0000] {taskinstance.py:1662} INFO - Exporting env vars: AIRFLOW_CTX_DAG_OWNER='***' AIRFLOW_CTX_DAG_ID='s3_hook_overview' AIRFLOW_CTX_TASK_ID='download_from_s3' AIRFLOW_CTX_EXECUTION_DATE='2023-12-13T00:00:00+00:00' AIRFLOW_CTX_TRY_NUMBER='2' AIRFLOW_CTX_DAG_RUN_ID='scheduled__2023-12-13T00:00:00+00:00'
[2023-12-14T02:01:43.169+0000] {s3.py:1366} INFO - This function shadows the 'download_file' method of S3 API, but it is not the same. If you want to use the original method from S3 API, please call 'S3Hook.get_conn().download_file()'
[2023-12-14T02:01:43.169+0000] {s3.py:1372} INFO - Downloading source S3 file from Bucket my-randon-bucket-001 with path Organizations-file
[2023-12-14T02:01:43.177+0000] {base_aws.py:581} WARNING - Unable to find AWS Connection ID 'awd_default', switching to empty.
[2023-12-14T02:01:43.178+0000] {base_aws.py:161} INFO - No connection ID provided. Fallback on boto3 credential strategy (region_name=None). See: https://boto3.amazonaws.com/v1/documentation/api/latest/guide/configuration.html
[2023-12-14T02:01:45.311+0000] {taskinstance.py:1937} ERROR - Task failed with exception
Traceback (most recent call last):
  File "/home/airflow/.local/lib/python3.8/site-packages/airflow/operators/python.py", line 192, in execute
    return_value = self.execute_callable()
  File "/home/airflow/.local/lib/python3.8/site-packages/airflow/operators/python.py", line 209, in execute_callable
    return self.python_callable(*self.op_args, **self.op_kwargs)
  File "/opt/airflow/dags/load_into_snowflake.py", line 23, in download_from_s3
    file_name = hook.download_file(key=s3_key, bucket_name=s3_bucket)
  File "/home/airflow/.local/lib/python3.8/site-packages/airflow/providers/amazon/aws/hooks/s3.py", line 135, in wrapper
    return func(*bound_args.args, **bound_args.kwargs)
  File "/home/airflow/.local/lib/python3.8/site-packages/airflow/providers/amazon/aws/hooks/s3.py", line 89, in wrapper
    return func(*bound_args.args, **bound_args.kwargs)
  File "/home/airflow/.local/lib/python3.8/site-packages/airflow/providers/amazon/aws/hooks/s3.py", line 1375, in download_file
    s3_obj = self.get_key(key, bucket_name)
  File "/home/airflow/.local/lib/python3.8/site-packages/airflow/providers/amazon/aws/hooks/s3.py", line 135, in wrapper
    return func(*bound_args.args, **bound_args.kwargs)
  File "/home/airflow/.local/lib/python3.8/site-packages/airflow/providers/amazon/aws/hooks/s3.py", line 89, in wrapper
    return func(*bound_args.args, **bound_args.kwargs)
  File "/home/airflow/.local/lib/python3.8/site-packages/airflow/providers/amazon/aws/hooks/s3.py", line 932, in get_key
    obj.load(**sanitize_extra_args())
  File "/home/airflow/.local/lib/python3.8/site-packages/boto3/resources/factory.py", line 564, in do_action
    response = action(self, *args, **kwargs)
  File "/home/airflow/.local/lib/python3.8/site-packages/boto3/resources/action.py", line 88, in __call__
    response = getattr(parent.meta.client, operation_name)(*args, **params)
  File "/home/airflow/.local/lib/python3.8/site-packages/botocore/client.py", line 535, in _api_call
    return self._make_api_call(operation_name, kwargs)
  File "/home/airflow/.local/lib/python3.8/site-packages/botocore/client.py", line 963, in _make_api_call
    http, parsed_response = self._make_request(
  File "/home/airflow/.local/lib/python3.8/site-packages/botocore/client.py", line 986, in _make_request
    return self._endpoint.make_request(operation_model, request_dict)
  File "/home/airflow/.local/lib/python3.8/site-packages/botocore/endpoint.py", line 119, in make_request
    return self._send_request(request_dict, operation_model)
  File "/home/airflow/.local/lib/python3.8/site-packages/botocore/endpoint.py", line 198, in _send_request
    request = self.create_request(request_dict, operation_model)
  File "/home/airflow/.local/lib/python3.8/site-packages/botocore/endpoint.py", line 134, in create_request
    self._event_emitter.emit(
  File "/home/airflow/.local/lib/python3.8/site-packages/botocore/hooks.py", line 412, in emit
    return self._emitter.emit(aliased_event_name, **kwargs)
  File "/home/airflow/.local/lib/python3.8/site-packages/botocore/hooks.py", line 256, in emit
    return self._emit(event_name, kwargs)
  File "/home/airflow/.local/lib/python3.8/site-packages/botocore/hooks.py", line 239, in _emit
    response = handler(**kwargs)
  File "/home/airflow/.local/lib/python3.8/site-packages/botocore/signers.py", line 105, in handler
    return self.sign(operation_name, request)
  File "/home/airflow/.local/lib/python3.8/site-packages/botocore/signers.py", line 189, in sign
    auth.add_auth(request)
  File "/home/airflow/.local/lib/python3.8/site-packages/botocore/auth.py", line 418, in add_auth
    raise NoCredentialsError()
botocore.exceptions.NoCredentialsError: Unable to locate credentials
[2023-12-14T02:01:45.335+0000] {taskinstance.py:1400} INFO - Marking task as FAILED. dag_id=s3_hook_overview, task_id=download_from_s3, execution_date=20231213T000000, start_date=20231214T020143, end_date=20231214T020145
[2023-12-14T02:01:45.374+0000] {standard_task_runner.py:104} ERROR - Failed to execute job 91 for task download_from_s3 (Unable to locate credentials; 4217)
[2023-12-14T02:01:45.403+0000] {local_task_job_runner.py:228} INFO - Task exited with return code 1
[2023-12-14T02:01:45.459+0000] {taskinstance.py:2778} INFO - 0 downstream tasks scheduled from follow-on schedule check
