[2023-12-16T06:36:06.597+0000] {taskinstance.py:1159} INFO - Dependencies all met for dep_context=non-requeueable deps ti=<TaskInstance: restapi-pipeline.json_file_upload_s3 manual__2023-12-16T06:35:38.551517+00:00 [queued]>
[2023-12-16T06:36:06.601+0000] {taskinstance.py:1159} INFO - Dependencies all met for dep_context=requeueable deps ti=<TaskInstance: restapi-pipeline.json_file_upload_s3 manual__2023-12-16T06:35:38.551517+00:00 [queued]>
[2023-12-16T06:36:06.601+0000] {taskinstance.py:1361} INFO - Starting attempt 3 of 3
[2023-12-16T06:36:06.606+0000] {taskinstance.py:1382} INFO - Executing <Task(PythonOperator): json_file_upload_s3> on 2023-12-16 06:35:38.551517+00:00
[2023-12-16T06:36:06.609+0000] {standard_task_runner.py:57} INFO - Started process 7716 to run task
[2023-12-16T06:36:06.612+0000] {standard_task_runner.py:84} INFO - Running: ['***', 'tasks', 'run', 'restapi-pipeline', 'json_file_upload_s3', 'manual__2023-12-16T06:35:38.551517+00:00', '--job-id', '288', '--raw', '--subdir', 'DAGS_FOLDER/restapi.py', '--cfg-path', '/tmp/tmpranojf4w']
[2023-12-16T06:36:06.613+0000] {standard_task_runner.py:85} INFO - Job 288: Subtask json_file_upload_s3
[2023-12-16T06:36:06.638+0000] {task_command.py:416} INFO - Running <TaskInstance: restapi-pipeline.json_file_upload_s3 manual__2023-12-16T06:35:38.551517+00:00 [running]> on host e65e9d73b232
[2023-12-16T06:36:06.679+0000] {taskinstance.py:1662} INFO - Exporting env vars: AIRFLOW_CTX_DAG_OWNER='sarthak' AIRFLOW_CTX_DAG_ID='restapi-pipeline' AIRFLOW_CTX_TASK_ID='json_file_upload_s3' AIRFLOW_CTX_EXECUTION_DATE='2023-12-16T06:35:38.551517+00:00' AIRFLOW_CTX_TRY_NUMBER='3' AIRFLOW_CTX_DAG_RUN_ID='manual__2023-12-16T06:35:38.551517+00:00'
[2023-12-16T06:36:07.895+0000] {taskinstance.py:1937} ERROR - Task failed with exception
Traceback (most recent call last):
  File "/home/airflow/.local/lib/python3.8/site-packages/boto3/s3/transfer.py", line 292, in upload_file
    future.result()
  File "/home/airflow/.local/lib/python3.8/site-packages/s3transfer/futures.py", line 103, in result
    return self._coordinator.result()
  File "/home/airflow/.local/lib/python3.8/site-packages/s3transfer/futures.py", line 266, in result
    raise self._exception
  File "/home/airflow/.local/lib/python3.8/site-packages/s3transfer/tasks.py", line 139, in __call__
    return self._execute_main(kwargs)
  File "/home/airflow/.local/lib/python3.8/site-packages/s3transfer/tasks.py", line 162, in _execute_main
    return_value = self._main(**kwargs)
  File "/home/airflow/.local/lib/python3.8/site-packages/s3transfer/upload.py", line 764, in _main
    client.put_object(Bucket=bucket, Key=key, Body=body, **extra_args)
  File "/home/airflow/.local/lib/python3.8/site-packages/botocore/client.py", line 535, in _api_call
    return self._make_api_call(operation_name, kwargs)
  File "/home/airflow/.local/lib/python3.8/site-packages/botocore/client.py", line 980, in _make_api_call
    raise error_class(parsed_response, operation_name)
botocore.errorfactory.NoSuchBucket: An error occurred (NoSuchBucket) when calling the PutObject operation: The specified bucket does not exist

During handling of the above exception, another exception occurred:

Traceback (most recent call last):
  File "/home/airflow/.local/lib/python3.8/site-packages/airflow/operators/python.py", line 192, in execute
    return_value = self.execute_callable()
  File "/home/airflow/.local/lib/python3.8/site-packages/airflow/operators/python.py", line 209, in execute_callable
    return self.python_callable(*self.op_args, **self.op_kwargs)
  File "/opt/airflow/dags/restapi.py", line 56, in upload_file_json
    client.upload_file('/opt/airflow/files/test.json', 'my-random-bucket-002','coin-price-json')
  File "/home/airflow/.local/lib/python3.8/site-packages/boto3/s3/inject.py", line 143, in upload_file
    return transfer.upload_file(
  File "/home/airflow/.local/lib/python3.8/site-packages/boto3/s3/transfer.py", line 298, in upload_file
    raise S3UploadFailedError(
boto3.exceptions.S3UploadFailedError: Failed to upload /opt/***/files/test.json to my-random-bucket-002/coin-price-json: An error occurred (NoSuchBucket) when calling the PutObject operation: The specified bucket does not exist
[2023-12-16T06:36:07.918+0000] {taskinstance.py:1400} INFO - Marking task as FAILED. dag_id=restapi-pipeline, task_id=json_file_upload_s3, execution_date=20231216T063538, start_date=20231216T063606, end_date=20231216T063607
[2023-12-16T06:36:07.931+0000] {standard_task_runner.py:104} ERROR - Failed to execute job 288 for task json_file_upload_s3 (Failed to upload /opt/***/files/test.json to my-random-bucket-002/coin-price-json: An error occurred (NoSuchBucket) when calling the PutObject operation: The specified bucket does not exist; 7716)
[2023-12-16T06:36:07.969+0000] {local_task_job_runner.py:228} INFO - Task exited with return code 1
[2023-12-16T06:36:07.992+0000] {taskinstance.py:2778} INFO - 0 downstream tasks scheduled from follow-on schedule check
