[2023-12-11T18:43:49.256+0000] {taskinstance.py:1159} INFO - Dependencies all met for dep_context=non-requeueable deps ti=<TaskInstance: s3_hook_overview.rename_file manual__2023-12-11T18:38:25.059610+00:00 [queued]>
[2023-12-11T18:43:49.262+0000] {taskinstance.py:1159} INFO - Dependencies all met for dep_context=requeueable deps ti=<TaskInstance: s3_hook_overview.rename_file manual__2023-12-11T18:38:25.059610+00:00 [queued]>
[2023-12-11T18:43:49.263+0000] {taskinstance.py:1361} INFO - Starting attempt 2 of 2
[2023-12-11T18:43:49.273+0000] {taskinstance.py:1382} INFO - Executing <Task(PythonOperator): rename_file> on 2023-12-11 18:38:25.059610+00:00
[2023-12-11T18:43:49.276+0000] {standard_task_runner.py:57} INFO - Started process 2760 to run task
[2023-12-11T18:43:49.280+0000] {standard_task_runner.py:84} INFO - Running: ['***', 'tasks', 'run', 's3_hook_overview', 'rename_file', 'manual__2023-12-11T18:38:25.059610+00:00', '--job-id', '28', '--raw', '--subdir', 'DAGS_FOLDER/load_into_snowflake.py', '--cfg-path', '/tmp/tmpvv2ybar5']
[2023-12-11T18:43:49.282+0000] {standard_task_runner.py:85} INFO - Job 28: Subtask rename_file
[2023-12-11T18:43:49.312+0000] {task_command.py:416} INFO - Running <TaskInstance: s3_hook_overview.rename_file manual__2023-12-11T18:38:25.059610+00:00 [running]> on host a3992be7c3a0
[2023-12-11T18:43:49.365+0000] {taskinstance.py:1662} INFO - Exporting env vars: AIRFLOW_CTX_DAG_OWNER='***' AIRFLOW_CTX_DAG_ID='s3_hook_overview' AIRFLOW_CTX_TASK_ID='rename_file' AIRFLOW_CTX_EXECUTION_DATE='2023-12-11T18:38:25.059610+00:00' AIRFLOW_CTX_TRY_NUMBER='2' AIRFLOW_CTX_DAG_RUN_ID='manual__2023-12-11T18:38:25.059610+00:00'
[2023-12-11T18:43:49.374+0000] {taskinstance.py:1937} ERROR - Task failed with exception
Traceback (most recent call last):
  File "/home/airflow/.local/lib/python3.8/site-packages/airflow/operators/python.py", line 192, in execute
    return_value = self.execute_callable()
  File "/home/airflow/.local/lib/python3.8/site-packages/airflow/operators/python.py", line 209, in execute_callable
    return self.python_callable(*self.op_args, **self.op_kwargs)
  File "/opt/airflow/dags/load_into_snowflake.py", line 125, in rename_file
    os.rename(src=downloaded_file_name, dst=new_path)
OSError: [Errno 16] Device or resource busy: '/' -> '/tmp/file_downloaded_from_s3.txt'
[2023-12-11T18:43:49.382+0000] {taskinstance.py:1400} INFO - Marking task as FAILED. dag_id=s3_hook_overview, task_id=rename_file, execution_date=20231211T183825, start_date=20231211T184349, end_date=20231211T184349
[2023-12-11T18:43:49.389+0000] {standard_task_runner.py:104} ERROR - Failed to execute job 28 for task rename_file ([Errno 16] Device or resource busy: '/' -> '/tmp/file_downloaded_from_s3.txt'; 2760)
[2023-12-11T18:43:49.412+0000] {local_task_job_runner.py:228} INFO - Task exited with return code 1
[2023-12-11T18:43:49.425+0000] {taskinstance.py:2778} INFO - 0 downstream tasks scheduled from follow-on schedule check
