[2023-12-15T08:09:53.184+0000] {taskinstance.py:1159} INFO - Dependencies all met for dep_context=non-requeueable deps ti=<TaskInstance: snow_pipeline.creating_tables scheduled__2023-12-14T00:00:00+00:00 [queued]>
[2023-12-15T08:09:53.189+0000] {taskinstance.py:1159} INFO - Dependencies all met for dep_context=requeueable deps ti=<TaskInstance: snow_pipeline.creating_tables scheduled__2023-12-14T00:00:00+00:00 [queued]>
[2023-12-15T08:09:53.189+0000] {taskinstance.py:1361} INFO - Starting attempt 3 of 3
[2023-12-15T08:09:53.196+0000] {taskinstance.py:1382} INFO - Executing <Task(SnowflakeOperator): creating_tables> on 2023-12-14 00:00:00+00:00
[2023-12-15T08:09:53.201+0000] {standard_task_runner.py:57} INFO - Started process 665 to run task
[2023-12-15T08:09:53.204+0000] {standard_task_runner.py:84} INFO - Running: ['***', 'tasks', 'run', 'snow_pipeline', 'creating_tables', 'scheduled__2023-12-14T00:00:00+00:00', '--job-id', '217', '--raw', '--subdir', 'DAGS_FOLDER/snowflake_dag.py', '--cfg-path', '/tmp/tmp9a1l9zz3']
[2023-12-15T08:09:53.206+0000] {standard_task_runner.py:85} INFO - Job 217: Subtask creating_tables
[2023-12-15T08:09:53.237+0000] {task_command.py:416} INFO - Running <TaskInstance: snow_pipeline.creating_tables scheduled__2023-12-14T00:00:00+00:00 [running]> on host e65e9d73b232
[2023-12-15T08:09:53.277+0000] {taskinstance.py:1662} INFO - Exporting env vars: AIRFLOW_CTX_DAG_OWNER='sarthak' AIRFLOW_CTX_DAG_ID='snow_pipeline' AIRFLOW_CTX_TASK_ID='creating_tables' AIRFLOW_CTX_EXECUTION_DATE='2023-12-14T00:00:00+00:00' AIRFLOW_CTX_TRY_NUMBER='3' AIRFLOW_CTX_DAG_RUN_ID='scheduled__2023-12-14T00:00:00+00:00'
[2023-12-15T08:09:53.278+0000] {sql.py:274} INFO - Executing: 
create or replace table webpage(
webpage_sk int,
webpage_id varchar(20),
url varchar(100),
ad_count int);
create or replace table webpage_sales(
webpage_sk int,
orderno int,
qty int,
net_profit number(10,2)
);
[2023-12-15T08:09:53.290+0000] {taskinstance.py:1937} ERROR - Task failed with exception
Traceback (most recent call last):
  File "/home/airflow/.local/lib/python3.8/site-packages/airflow/providers/common/sql/operators/sql.py", line 275, in execute
    hook = self.get_db_hook()
  File "/home/airflow/.local/lib/python3.8/site-packages/airflow/providers/common/sql/operators/sql.py", line 186, in get_db_hook
    return self._hook
  File "/usr/local/lib/python3.8/functools.py", line 967, in __get__
    val = self.func(instance)
  File "/home/airflow/.local/lib/python3.8/site-packages/airflow/providers/common/sql/operators/sql.py", line 148, in _hook
    conn = BaseHook.get_connection(conn_id)
  File "/home/airflow/.local/lib/python3.8/site-packages/airflow/hooks/base.py", line 72, in get_connection
    conn = Connection.get_connection_from_secrets(conn_id)
  File "/home/airflow/.local/lib/python3.8/site-packages/airflow/models/connection.py", line 477, in get_connection_from_secrets
    raise AirflowNotFoundException(f"The conn_id `{conn_id}` isn't defined")
airflow.exceptions.AirflowNotFoundException: The conn_id `snowflake2` isn't defined
[2023-12-15T08:09:53.305+0000] {taskinstance.py:1400} INFO - Marking task as FAILED. dag_id=snow_pipeline, task_id=creating_tables, execution_date=20231214T000000, start_date=20231215T080953, end_date=20231215T080953
[2023-12-15T08:09:53.314+0000] {standard_task_runner.py:104} ERROR - Failed to execute job 217 for task creating_tables (The conn_id `snowflake2` isn't defined; 665)
[2023-12-15T08:09:53.337+0000] {local_task_job_runner.py:228} INFO - Task exited with return code 1
[2023-12-15T08:09:53.346+0000] {taskinstance.py:2778} INFO - 0 downstream tasks scheduled from follow-on schedule check
